Workbook

Sheet TASKS & INFO
A1: TASKS | B1: gen | C1: mcq | D1: Progress | E1: Concern
A2: Composition
A3: Diacritics (33% 2 diacritic, 33% 1, 33% 0) | B3: replace composition_gen > "diacritic" ok -- prompt ready | C3: use old dataset -- QCed: https://github.com/raileymontalan/pacute-bench/blob/main/data/benchmarks/composition_mcq.jsonl | D3: ok
A4: Uppercasing (33% >=2 uppercase, 33% 1, 33% 0) | B4: replace composition_gen > "uppercase" ok -- prompt ready | C4: "prompts":[{"text_en":"Which option contains exactly 1 \"K\" character\/s?","text_tl":"Alin sa sumusunod ang naglalaman ng eksaktong 1 titik na \"K\"?","mcq_options":{"correct":"Katipúnan","incorrect1":"katipúnan","incorrect2":"Kalát","incorrect3":"Kambíng"},"choice1":"katipúnan","choice2":"Kambíng","choice3":"Kalát","choice4":"Katipúnan"}] | D4: ok
A5: Character Counting | B5: replace composition_gen > "character_counting"
A6: Character Recognition | B6: replace composition_gen > "character_recognition"
A7: Morphological Extraction
A8: Inflected affix extraction (namula -> na) | B8: will replace affixation_gen > "affix_identification" | C8: TODO: correct, automate two, add one distractor | D8: ok
A9: Inflected root extraction (namula -> pula) | B9: new | D9: affix extraction dataset can double for root extraction | E9: should this be a different dataset?
A10: Reduplicated root extraction: 50% partial, 50% full (pupunta -> punta) | B10: new | D10: ok | E10: adjusted split to have more partial. it is more challenging to extract partial because of morpophonemic changes
A11: Reduplicant extraction: 100% partial (pupunta -> pu) | B11: remove syllabification_gen > "reduplication_identification" to replace with this new task under morphological_extraction | C11: remove syllabification_mcq > "reduplication_detection" to replace with this new task under morphologial_extraction Example prompt format -- "prompts": [{"text_en": "Which word has CV-reduplication (first consonant-vowel repeated)?", "text_tl": "Alin ang may uulit-pantig (inuulit ang unang katinig-patinig)?", "mcq_options": {"correct": "dibdib", "incorrect1": "nawa", "incorrect2": "tubog", "incorrect3": "banal"}}], "label": null, "id": "syllabification_mcq_00256"}
A12: Morphological Production
A13: Inflected form production (pula + na- -> namula) | B13: review Lance's gen > production (production_gen_00000 --> production_gen_00249) | E13: lapi -> panlapi
A14: Reduplicated form production (punta + future aspect -> pupunta) | B14: review Lance's gen > production (production_gen_00250 --> production_gen_00299)
A16: INFO
A17: Morphological Extraction (Inflection Tasks)
A18: Currently: 40 infix, suffix, prefix; 20 circumfix
A19: Reasonable goal: 40 infix, suffix, prefix; 20 circumfix with assimilation, phoneme change, metatesis, phoneme deletion
A30: Mga Pagbabagong Morpoponemiko
A31: Source: Makabagong Balarilang Filipino (Santiago & Tiangco, 2003)
A32: ID | B32: Transformation | C32: Description | D32: Applicability | E32: Illustration | G32: Count | H32: Affixes | I32: Affixes 2
A33: 1 | B33: Asimilasyon | C33: Nagbabago ang ponemang /ng/ at nagiging /m/, /n/, o nananatiling /ng/ | D33: prefix
A34: 1.1 | B34: Asimilasyong Di-Ganap (Partial Assimilation) | C34: Asimilasyon kung saan hindi nagbabago ang nilalapiang salita. | E34: pang + paaralan = pampaaralan | G34: 10 prefix | H34: hing-, ikang-, ikapakapang-, ikapang-, ipagkang-, ipang-, kasing-, magkang-, mang-, mapang-, nang-, pang-, sang- | I34: /
A35: 1.2 | B35: Asimilasyong Ganap | C35: Asimilasyon kung saan nawawala ang unang ponema ng nilalapiang salita. | E35: pang + palo = pampalo => pamalo | G35: 10 prefix | H35: hing-, ikang-, ikapakapang-, ikapang-, ipagkang-, ipang-, kasing-, magkang-, mang-, mapang-, pang-, sang- | I35: /
A36: 2 | B36: Pagpapalit ng Ponema | C36: Napapalitan ang ponema dahil sa pagbabago ng salita (hal., paglalapi) | D36: prefix, suffix | E36: ma + dapat = marapat tawa + han = tawanan | G36: 10 prefix, 20 suffix | H36: ikapa-, ikapagka-, ikapagpaka-, ikapakipa-, ka-, kaka-, ma-, mana-, mangagpa-, mangagsipagpa-, mapa-, mapaka-, mapasa-, maga-, na-, nagka-, nagpa-, nagpaka-, nagsa-, nakapagpa-, nakapagpaka-, napaka-, napasa-, pagka-, pagpapa-, pagpapaka-, pagsasa-, pampa-, pasa-, pasasa-, pina-, pinaka-, sa- | I36: /
A37: 3 | B37: Metatesis | C37: Kapag ang salitang-ugat na nagsisimula sa /l/ o /y/ ay ginitlapian ng [-in-], nagpapalit ng posisyon ang /l/ o /y/ at ang /n/ ng gitlapi | D37: infix | E37: in + lipad = nilipad | G37: 30 infix
A38: 4 | B38: Pagkakaltas ng Ponema | C38: Nawawala ng ponemang patinig ng huling pantig ng salitang nilalapian pag nilagyan ng hulapi. | D38: suffix | E38: takip + an = takpan | G38: 10 suffix
A41: Reduplication Reference
A42: https://soologua.wordpress.com/wp-content/uploads/2016/03/reduplication-in-tagalog-verbs.pdf
A43: https://www.jstor.org/stable/288967?seq=4
A44: https://www.urp.udel.edu/wp-content/uploads/2017/08/Tagalog-Phonology.pdf

Sheet morphological_extraction
A1: word | B1: root_word | C1: affix | D1: affix_alternate | E1: affix_type | F1: subtype
A2: mambola | B2: bola | C2: mang- | E2: prefix | F2: partial assimilation (prefix)
A3: mandaya | B3: daya | C3: mang- | E3: prefix | F3: partial assimilation (prefix)
A4: mapanlamang | B4: lamang | C4: mapang- | E4: prefix | F4: partial assimilation (prefix)
A5: pambansa | B5: bansa | C5: pang- | E5: prefix | F5: partial assimilation (prefix)
A6: pampito | B6: pito | C6: pang- | E6: prefix | F6: partial assimilation (prefix)
A7: nanlaban | B7: laban | C7: nang- | E7: prefix | F7: partial assimilation (prefix)
A8: ipampinta | B8: pinta | C8: nang- | E8: prefix | F8: partial assimilation (prefix)
A9: ipantapal | B9: tapal | C9: ipang- | E9: prefix | F9: partial assimilation (prefix)
A10: simbait | B10: bait | C10: sing- | E10: prefix | F10: partial assimilation (prefix)
A11: sintibay | B11: tibay | C11: sing- | E11: prefix | F11: partial assimilation (prefix)
A12: panguha | B12: kuha | C12: pang- | E12: prefix | F12: full assimilation (prefix)
A13: panabas | B13: tabas | C13: pang- | E13: prefix | F13: full assimilation (prefix)
... A64: sabugan | B64: sabog | C64: -an | E64: suffix | F64: phoneme change (suffix)
A65: batuhin | B65: bato | C65: -hin | D65: -in | E65: suffix | F65: phoneme change (suffix)
A66: sikuhin | B66: siko | C66: -hin | D66: -in | E66: suffix | F66: phoneme change (suffix)
A67: puruhan | B67: puro | C67: -han | D67: -an | E67: suffix | F67: phoneme change (suffix)
A68: baguhin | B68: bago | C68: -hin | D68: -in | E68: suffix | F68: phoneme change (suffix)
A69: uluhan | B69: ulo | C69: -han | D69: -an | E69: suffix | F69: phoneme change (suffix)
A70: guluhin | B70: gulo | C70: -hin | D70: -in | E70: suffix | F70: phoneme change (suffix)
A71: tawanan | B71: tawa | C71: -han | D71: -an | E71: suffix | F71: phoneme change (suffix)
A72: takpan | B72: takip | C72: -an | E72: suffix | F72: phoneme deletion (suffix)
A73: saktan | B73: sakit | C73: -an | E73: suffix | F73: phoneme deletion (suffix)
A74: buksan | B74: bukas | C74: -an | E74: suffix | F74: phoneme deletion (suffix)
A75: sundin | B75: sunod | C75: -in | E75: suffix | F75: phoneme deletion (suffix)
A76: tupdin | B76: tupad | C76: -in | E76: suffix | F76: phoneme deletion (suffix)
A77: bigyan | B77: bigay | C77: -an | E77: suffix | F77: phoneme deletion (suffix)
A78: dinggin | B78: dinig | C78: -in | E78: suffix | F78: phoneme deletion (suffix)
A79: lagyan | B79: lagay | C79: -an | E79: suffix | F79: phoneme deletion (suffix)
A80: tikman | B80: tikim | C80: -an | E80: suffix | F80: phoneme deletion (suffix)
A81: bilhin | B81: bili | C81: -hin | D81: -in | E81: suffix | F81: phoneme deletion (suffix)
A82: takasan | B82: takas | C82: -an | E82: suffix | F82: regular inflection
A83: labanan | B83: laban | C83: -an | E83: suffix | F83: regular inflection
A84: sulatan | B84: sulat | C84: -an | E84: suffix | F84: regular inflection
A85: titigan | B85: titig | C85: -an | E85: suffix | F85: regular inflection
A86: awitan | B86: awit | C86: -an | E86: suffix | F86: regular inflection
A87: asahan | B87: asa | C87: -han | D87: -an | E87: suffix | F87: regular inflection
A88: abonohan | B88: abono | C88: -han | D88: -an | E88: suffix | F88: regular inflection
A89: suportahan | B89: suporta | C89: -han | D89: -an | E89: suffix | F89: regular inflection
A90: agahan | B90: aga | C90: -han | D90: -an | E90: suffix | F90: regular inflection
...

Sheet diacritics
A1: category | B1: subcategory | C1: text_en | D1: text_tl | E1: label | F1: id | G1: diacritized_word | H1: normalized_form | I1: diacritics_count
A2: composition | B2: diacritics | C2: ="How many diacritized vowels are in the word " & "\" & """" & G2 & "\" & """" & "?" -> How many diacritized vowels are in the word \"at\"? | D2: ="Ilang patinig ang mayroong tuldik sa salitang " & "\" & """" & G2 & "\" & """" & "?" -> Ilang patinig ang mayroong tuldik sa salitang \"at\"? | E2: =I2 -> 0 | F2: composition_diacritics_00000 | G2: at | H2: at | I2: 0
A3: composition | B3: diacritics | C3: ="How many diacritized vowels are in the word " & "\" & """" & G3 & "\" & """" & "?" -> How many diacritized vowels are in the word \"mo\"? | D3: ="Ilang patinig ang mayroong tuldik sa salitang " & "\" & """" & G3 & "\" & """" & "?" -> Ilang patinig ang mayroong tuldik sa salitang \"mo\"? | E3: =I3 -> 0 | F3: composition_diacritics_00001 | G3: mo | H3: mo | I3: 0
A4: composition | B4: diacritics | C4: ="How many diacritized vowels are in the word " & "\" & """" & G4 & "\" & """" & "?" -> How many diacritized vowels are in the word \"ko\"? | D4: ="Ilang patinig ang mayroong tuldik sa salitang " & "\" & """" & G4 & "\" & """" & "?" -> Ilang patinig ang mayroong tuldik sa salitang \"ko\"? | E4: =I4 -> 0 | F4: composition_diacritics_00002 | G4: ko | H4: ko | I4: 0
A5: composition | B5: diacritics | C5: ="How many diacritized vowels are in the word " & "\" & """" & G5 & "\" & """" & "?" -> How many diacritized vowels are in the word \"ng\"? | D5: ="Ilang patinig ang mayroong tuldik sa salitang " & "\" & """" & G5 & "\" & """" & "?" -> Ilang patinig ang mayroong tuldik sa salitang \"ng\"? | E5: =I5 -> 0 | F5: composition_diacritics_00003 | G5: ng | H5: ng | I5: 0
A6: composition | B6: diacritics | C6: ="How many diacritized vowels are in the word " & "\" & """" & G6 & "\" & """" & "?" -> How many diacritized vowels are in the word \"ang\"? | D6: ="Ilang patinig ang mayroong tuldik sa salitang " & "\" & """" & G6 & "\" & """" & "?" -> Ilang patinig ang mayroong tuldik sa salitang \"ang\"? | E6: =I6 -> 0 | F6: composition_diacritics_00004 | G6: ang | H6: ang | I6: 0
A7: composition | B7: diacritics | C7: ="How many diacritized vowels are in the word " & "\" & """" & G7 & "\" & """" & "?" -> How many diacritized vowels are in the word \"sa\"? | D7: ="Ilang patinig ang mayroong tuldik sa salitang " & "\" & """" & G7 & "\" & """" & "?" -> Ilang patinig ang mayroong tuldik sa salitang \"sa\"? | E7: =I7 -> 0 | F7: composition_diacritics_00005 | G7: sa | H7: sa | I7: 0
A8: composition | B8: diacritics | C8: ="How many diacritized vowels are in the word " & "\" & """" & G8 & "\" & """" & "?" -> How many diacritized vowels are in the word \"pa\"? | D8: ="Ilang patinig ang mayroong tuldik sa salitang " & "\" & """" & G8 & "\" & """" & "?" -> Ilang patinig ang mayroong tuldik sa salitang \"pa\"? | E8: =I8 -> 0 | F8: composition_diacritics_00006 | G8: pa | H8: pa | I8: 0
A9: composition | B9: diacritics | C9: ="How many diacritized vowels are in the word " & "\" & """" & G9 & "\" & """" & "?" -> How many diacritized vowels are in the word \"ka\"? | D9: ="Ilang patinig ang mayroong tuldik sa salitang " & "\" & """" & G9 & "\" & """" & "?" -> Ilang patinig ang mayroong tuldik sa salitang \"ka\"? | E9: =I9 -> 0 | F9: composition_diacritics_00007 | G9: ka | H9: ka | I9: 0
A10: composition | B10: diacritics | C10: ="How many diacritized vowels are in the word " & "\" & """" & G10 & "\" & """" & "?" -> How many diacritized vowels are in the word \"kung\"? | D10: ="Ilang patinig ang mayroong tuldik sa salitang " & "\" & """" & G10 & "\" & """" & "?" -> Ilang patinig ang mayroong tuldik sa salitang \"kung\"? | E10: =I10 -> 0 | F10: composition_diacritics_00008 | G10: kung | H10: kung | I10: 0
A11: composition | B11: diacritics | C11: ="How many diacritized vowels are in the word " & "\" & """" & G11 & "\" & """" & "?" -> How many diacritized vowels are in the word \"ba\"? | D11: ="Ilang patinig ang mayroong tuldik sa salitang " & "\" & """" & G11 & "\" & """" & "?" -> Ilang patinig ang mayroong tuldik sa salitang \"ba\"? | E11: =I11 -> 0 | F11: composition_diacritics_00009 | G11: ba | H11: ba | I11: 0
A12: composition | B12: diacritics | C12: ="How many diacritized vowels are in the word " & "\" & """" & G12 & "\" & """" & "?" -> How many diacritized vowels are in the word \"beyk\"? | D12: ="Ilang patinig ang mayroong tuldik sa salitang " & "\" & """" & G12 & "\" & """" & "?" -> Ilang patinig ang mayroong tuldik sa salitang \"beyk\"? | E12: =I12 -> 0 | F12: composition_diacritics_00010 | G12: beyk | H12: beyk | I12: 0
A13: composition | B13: diacritics | C13: ="How many diacritized vowels are in the word " & "\" & """" & G13 & "\" & """" & "?" -> How many diacritized vowels are in the word \"bus\"? | D13: ="Ilang patinig ang mayroong tuldik sa salitang " & "\" & """" & G13 & "\" & """" & "?" -> Ilang patinig ang mayroong tuldik sa salitang \"bus\"? | E13: =I13 -> 0 | F13: composition_diacritics_00011 | G13: bus | H13: bus | I13: 0
... A168: composition | B168: diacritics | C168: ="How many diacritized vowels are in the word " & "\" & """" & G168 & "\" & """" & "?" -> How many diacritized vowels are in the word \"pawálang-bisà\"? | D168: ="Ilang patinig ang mayroong tuldik sa salitang " & "\" & """" & G168 & "\" & """" & "?" -> Ilang patinig ang mayroong tuldik sa salitang \"pawálang-bisà\"? | E168: =I168 -> 2 | F168: composition_diacritics_00166 | G168: pawálang-bisà | H168: pawalang-bisa | I168: 2

Sheet uppercasing
A1: category | B1: subcategory | C1: text_en | D1: text_tl | E1: label | F1: id | G1: word | H1: normalized_form | I1: uppercase_count
A2: composition | B2: uppercase | C2: ="How many uppercase letters are in the word " & "\" & """" & G2 & "\" & """" & "?" -> How many uppercase letters are in the word \"do-om\"? | D2: ="Ilang malaking titik ang mayroon sa salitang " & "\" & """" & G2 & "\" & """" & "?" -> Ilang malaking titik ang mayroon sa salitang \"do-om\"? | E2: =I2 -> 0 | F2: composition_uppercase_00000 | G2: do-om | H2: do-om | I2: 0
A3: composition | B3: uppercase | C3: ="How many uppercase letters are in the word " & "\" & """" & G3 & "\" & """" & "?" -> How many uppercase letters are in the word \"pidot\"? | D3: ="Ilang malaking titik ang mayroon sa salitang " & "\" & """" & G3 & "\" & """" & "?" -> Ilang malaking titik ang mayroon sa salitang \"pidot\"? | E3: =I3 -> 0 | F3: composition_uppercase_00001 | G3: pidot | H3: pidot | I3: 0
A4: composition | B4: uppercase | C4: ="How many uppercase letters are in the word " & "\" & """" & G4 & "\" & """" & "?" -> How many uppercase letters are in the word \"longhand\"? | D4: ="Ilang malaking titik ang mayroon sa salitang " & "\" & """" & G4 & "\" & """" & "?" -> Ilang malaking titik ang mayroon sa salitang \"longhand\"? | E4: =I4 -> 0 | F4: composition_uppercase_00002 | G4: longhand | H4: longhand | I4: 0
A5: composition | B5: uppercase | C5: ="How many uppercase letters are in the word " & "\" & """" & G5 & "\" & """" & "?" -> How many uppercase letters are in the word \"multikolor\"? | D5: ="Ilang malaking titik ang mayroon sa salitang " & "\" & """" & G5 & "\" & """" & "?" -> Ilang malaking titik ang mayroon sa salitang \"multikolor\"? | E5: =I5 -> 0 | F5: composition_uppercase_00003 | G5: multikolor | H5: multikolor | I5: 0
A6: composition | B6: uppercase | C6: ="How many uppercase letters are in the word " & "\" & """" & G6 & "\" & """" & "?" -> How many uppercase letters are in the word \"mamulubi\"? | D6: ="Ilang malaking titik ang mayroon sa salitang " & "\" & """" & G6 & "\" & """" & "?" -> Ilang malaking titik ang mayroon sa salitang \"mamulubi\"? | E6: =I6 -> 0 | F6: composition_uppercase_00004 | G6: mamulubi | H6: mamulubi | I6: 0
A7: composition | B7: uppercase | C7: ="How many uppercase letters are in the word " & "\" & """" & G7 & "\" & """" & "?" -> How many uppercase letters are in the word \"inosente\"? | D7: ="Ilang malaking titik ang mayroon sa salitang " & "\" & """" & G7 & "\" & """" & "?" -> Ilang malaking titik ang mayroon sa salitang \"inosente\"? | E7: =I7 -> 0 | F7: composition_uppercase_00005 | G7: inosente | H7: inosente | I7: 0
A8: composition | B8: uppercase | C8: ="How many uppercase letters are in the word " & "\" & """" & G8 & "\" & """" & "?" -> How many uppercase letters are in the word \"sensum\"? | D8: ="Ilang malaking titik ang mayroon sa salitang " & "\" & """" & G8 & "\" & """" & "?" -> Ilang malaking titik ang mayroon sa salitang \"sensum\"? | E8: =I8 -> 0 | F8: composition_uppercase_00006 | G8: sensum | H8: sensum | I8: 0
A9: composition | B9: uppercase | C9: ="How many uppercase letters are in the word " & "\" & """" & G9 & "\" & """" & "?" -> How many uppercase letters are in the word \"odontolohiya\"? | D9: ="Ilang malaking titik ang mayroon sa salitang " & "\" & """" & G9 & "\" & """" & "?" -> Ilang malaking titik ang mayroon sa salitang \"odontolohiya\"? | E9: =I9 -> 0 | F9: composition_uppercase_00007 | G9: odontolohiya | H9: odontolohiya | I9: 0
A10: composition | B10: uppercase | C10: ="How many uppercase letters are in the word " & "\" & """" & G10 & "\" & """" & "?" -> How many uppercase letters are in the word \"hoyang\"? | D10: ="Ilang malaking titik ang mayroon sa salitang " & "\" & """" & G10 & "\" & """" & "?" -> Ilang malaking titik ang mayroon sa salitang \"hoyang\"? | E10: =I10 -> 0 | F10: composition_uppercase_00008 | G10: hoyang | H10: hoyang | I10: 0
A11: composition | B11: uppercase | C11: ="How many uppercase letters are in the word " & "\" & """" & G11 & "\" & """" & "?" -> How many uppercase letters are in the word \"norm\"? | D11: ="Ilang malaking titik ang mayroon sa salitang " & "\" & """" & G11 & "\" & """" & "?" -> Ilang malaking titik ang mayroon sa salitang \"norm\"? | E11: =I11 -> 0 | F11: composition_uppercase_00009 | G11: norm | H11: norm | I11: 0
A12: composition | B12: uppercase | C12: ="How many uppercase letters are in the word " & "\" & """" & G12 & "\" & """" & "?" -> How many uppercase letters are in the word \"talisayan\"? | D12: ="Ilang malaking titik ang mayroon sa salitang " & "\" & """" & G12 & "\" & """" & "?" -> Ilang malaking titik ang mayroon sa salitang \"talisayan\"? | E12: =I12 -> 0 | F12: composition_uppercase_00010 | G12: talisayan | H12: talisayan | I12: 0
A13: composition | B13: uppercase | C13: ="How many uppercase letters are in the word " & "\" & """" & G13 & "\" & """" & "?" -> How many uppercase letters are in the word \"iwit\"? | D13: ="Ilang malaking titik ang mayroon sa salitang " & "\" & """" & G13 & "\" & """" & "?" -> Ilang malaking titik ang mayroon sa salitang \"iwit\"? | E13: =I13 -> 0 | F13: composition_uppercase_00011 | G13: iwit | H13: iwit | I13: 0
... A269: composition | B269: uppercase | C269: ="How many uppercase letters are in the word " & "\" & """" & G269 & "\" & """" & "?" -> How many uppercase letters are in the word \"Holy City\"? | D269: ="Ilang malaking titik ang mayroon sa salitang " & "\" & """" & G269 & "\" & """" & "?" -> Ilang malaking titik ang mayroon sa salitang \"Holy City\"? | E269: =I269 -> 2 | F269: composition_uppercase_00267 | G269: Holy City | H269: holy city | I269: 2

Sheet character_counting
A1: category | B1: subcategory | C1: subcategory2 | D1: text_en | E1: text_tl | F1: label | G1: id | H1: word | I1: word_x
A2: composition | B2: character_counting | C2: regular | D2: How many letters are in the word \"gabi-gabi\"? | E2: Ilang titik mayroon ang salitang \"gabi-gabi\"? | F2: 8 | G2: composition_character_counting_00001 | H2: gabi-gabi | I2: =SUBSTITUTE(SUBSTITUTE(H2,"-",""),"ng","x") -> gabigabi | J2: =IF(COUNTIF(H:H, H2)>1,"Duplicate","Unique") -> Unique
A3: composition | B3: character_counting | C3: regular | D3: ="How many letters are in the word " & "\" & """" &H3 & "\" & """" & "?""" -> How many letters are in the word \"nagsipagwasiwas\"?" | E3: ="Ilang titik mayroon ang salitang " & "\" & """" &H3 & "\" & """" & "?""" -> Ilang titik mayroon ang salitang \"nagsipagwasiwas\"?" | F3: 15 | G3: composition_character_counting_00002 | H3: nagsipagwasiwas | I3: =SUBSTITUTE(SUBSTITUTE(H3,"-",""),"ng","x") -> nagsipagwasiwas | J3: =IF(COUNTIF(H:H, H3)>1,"Duplicate","Unique") -> Unique
A4: composition | B4: character_counting | C4: regular | D4: ="How many letters are in the word " & "\" & """" &H4 & "\" & """" & "?""" -> How many letters are in the word \"niliguyan\"?" | E4: ="Ilang titik mayroon ang salitang " & "\" & """" &H4 & "\" & """" & "?""" -> Ilang titik mayroon ang salitang \"niliguyan\"?" | F4: 9 | G4: composition_character_counting_00003 | H4: niliguyan | I4: =SUBSTITUTE(SUBSTITUTE(H4,"-",""),"ng","x") -> niliguyan | J4: =IF(COUNTIF(H:H, H4)>1,"Duplicate","Unique") -> Unique
A5: composition | B5: character_counting | C5: regular | D5: ="How many letters are in the word " & "\" & """" &H5 & "\" & """" & "?""" -> How many letters are in the word \"pakikihithit\"?" | E5: ="Ilang titik mayroon ang salitang " & "\" & """" &H5 & "\" & """" & "?""" -> Ilang titik mayroon ang salitang \"pakikihithit\"?" | F5: 12 | G5: composition_character_counting_00004 | H5: pakikihithit | I5: =SUBSTITUTE(SUBSTITUTE(H5,"-",""),"ng","x") -> pakikihithit | J5: =IF(COUNTIF(H:H, H5)>1,"Duplicate","Unique") -> Unique
A6: composition | B6: character_counting | C6: regular | D6: ="How many letters are in the word " & "\" & """" &H6 & "\" & """" & "?""" -> How many letters are in the word \"tigdalawa\"?" | E6: ="Ilang titik mayroon ang salitang " & "\" & """" &H6 & "\" & """" & "?""" -> Ilang titik mayroon ang salitang \"tigdalawa\"?" | F6: 9 | G6: composition_character_counting_00005 | H6: tigdalawa | I6: =SUBSTITUTE(SUBSTITUTE(H6,"-",""),"ng","x") -> tigdalawa | J6: =IF(COUNTIF(H:H, H6)>1,"Duplicate","Unique") -> Unique
A7: composition | B7: character_counting | C7: regular | D7: ="How many letters are in the word " & "\" & """" &H7 & "\" & """" & "?""" -> How many letters are in the word \"magkandalanta-lanta\"?" | E7: ="Ilang titik mayroon ang salitang " & "\" & """" &H7 & "\" & """" & "?""" -> Ilang titik mayroon ang salitang \"magkandalanta-lanta\"?" | F7: 18 | G7: composition_character_counting_00006 | H7: magkandalanta-lanta | I7: =SUBSTITUTE(SUBSTITUTE(H7,"-",""),"ng","x") -> magkandalantalanta | J7: =IF(COUNTIF(H:H, H7)>1,"Duplicate","Unique") -> Unique
A8: composition | B8: character_counting | C8: regular | D8: ="How many letters are in the word " & "\" & """" &H8 & "\" & """" & "?""" -> How many letters are in the word \"nakakapanrahuyo\"?" | E8: ="Ilang titik mayroon ang salitang " & "\" & """" &H8 & "\" & """" & "?""" -> Ilang titik mayroon ang salitang \"nakakapanrahuyo\"?" | F8: 15 | G8: composition_character_counting_00007 | H8: nakakapanrahuyo | I8: =SUBSTITUTE(SUBSTITUTE(H8,"-",""),"ng","x") -> nakakapanrahuyo | J8: =IF(COUNTIF(H:H, H8)>1,"Duplicate","Unique") -> Unique
A9: composition | B9: character_counting | C9: regular | D9: ="How many letters are in the word " & "\" & """" &H9 & "\" & """" & "?""" -> How many letters are in the word \"nakupitan\"?" | E9: ="Ilang titik mayroon ang salitang " & "\" & """" &H9 & "\" & """" & "?""" -> Ilang titik mayroon ang salitang \"nakupitan\"?" | F9: 9 | G9: composition_character_counting_00008 | H9: nakupitan | I9: =SUBSTITUTE(SUBSTITUTE(H9,"-",""),"ng","x") -> nakupitan | J9: =IF(COUNTIF(H:H, H9)>1,"Duplicate","Unique") -> Unique
A10: composition | B10: character_counting | C10: regular | D10: ="How many letters are in the word " & "\" & """" &H10 & "\" & """" & "?""" -> How many letters are in the word \"labintatlo\"?" | E10: ="Ilang titik mayroon ang salitang " & "\" & """" &H10 & "\" & """" & "?""" -> Ilang titik mayroon ang salitang \"labintatlo\"?" | F10: 10 | G10: composition_character_counting_00009 | H10: labintatlo | I10: =SUBSTITUTE(SUBSTITUTE(H10,"-",""),"ng","x") -> labintatlo | J10: =IF(COUNTIF(H:H, H10)>1,"Duplicate","Unique") -> Unique
A11: composition | B11: character_counting | C11: regular | D11: ="How many letters are in the word " & "\" & """" &H11 & "\" & """" & "?""" -> How many letters are in the word \"katwiran\"?" | E11: ="Ilang titik mayroon ang salitang " & "\" & """" &H11 & "\" & """" & "?""" -> Ilang titik mayroon ang salitang \"katwiran\"?" | F11: 8 | G11: composition_character_counting_00010 | H11: katwiran | I11: =SUBSTITUTE(SUBSTITUTE(H11,"-",""),"ng","x") -> katwiran | J11: =IF(COUNTIF(H:H, H11)>1,"Duplicate","Unique") -> Unique
A12: composition | B12: character_counting | C12: regular | D12: ="How many letters are in the word " & "\" & """" &H12 & "\" & """" & "?""" -> How many letters are in the word \"talaarawan\"?" | E12: ="Ilang titik mayroon ang salitang " & "\" & """" &H12 & "\" & """" & "?""" -> Ilang titik mayroon ang salitang \"talaarawan\"?" | F12: 10 | G12: composition_character_counting_00011 | H12: talaarawan | I12: =SUBSTITUTE(SUBSTITUTE(H12,"-",""),"ng","x") -> talaarawan | J12: =IF(COUNTIF(H:H, H12)>1,"Duplicate","Unique") -> Unique
A13: composition | B13: character_counting | C13: regular | D13: ="How many letters are in the word " & "\" & """" &H13 & "\" & """" & "?""" -> How many letters are in the word \"kakakain\"?" | E13: ="Ilang titik mayroon ang salitang " & "\" & """" &H13 & "\" & """" & "?""" -> Ilang titik mayroon ang salitang \"kakakain\"?" | F13: 8 | G13: composition_character_counting_00012 | H13: kakakain | I13: =SUBSTITUTE(SUBSTITUTE(H13,"-",""),"ng","x") -> kakakain | J13: =IF(COUNTIF(H:H, H13)>1,"Duplicate","Unique") -> Unique
A14: composition | B14: character_counting | C14: regular | D14: ="How many letters are in the word " & "\" & """" &H14 & "\" & """" & "?""" -> How many letters are in the word \"kabababa\"?" | E14: ="Ilang titik mayroon ang salitang " & "\" & """" &H14 & "\" & """" & "?""" -> Ilang titik mayroon ang salitang \"kabababa\"?" | F14: 8 | G14: composition_character_counting_00013 | H14: kabababa | I14: =SUBSTITUTE(SUBSTITUTE(H14,"-",""),"ng","x") -> kabababa | J14: =IF(COUNTIF(H:H, H14)>1,"Duplicate","Unique") -> Unique
... A101: composition | B101: character_counting | C101: ng_aware | D101: ="How many letters are in the word " & "\" & """" &H101 & "\" & """" & "?""" -> How many letters are in the word \"ungol\"?" | E101: ="Ilang titik mayroon ang salitang " & "\" & """" &H101 & "\" & """" & "?""" -> Ilang titik mayroon ang salitang \"ungol\"?" | F101: 4 | G101: composition_character_counting_00100 | H101: ungol | I101: =SUBSTITUTE(SUBSTITUTE(H101,"-",""),"ng","x") -> uxol | J101: =IF(COUNTIF(H:H, H101)>1,"Duplicate","Unique") -> Unique

Sheet character_recognition
A1: category | B1: subcategory | C1: subcategory2 | D1: text_en | E1: text_tl | F1: label | G1: id | I1: word | J1: position_english | K1: position
A2: composition | B2: character_recognition | C2: regular | D2: What is the 6th letter of the word \"ampunin\"'? | E2: Ano ang ika-6 na titik ng salitang \"ampunin\"? | F2: i | G2: composition_character_recognition_00000 | I2: ampunin | J2: 6th | K2: 6
A3: composition | B3: character_recognition | C3: regular | D3: ="What is the " & J3 & " letter of the word " & "\" & """" &I3 & "\" & """" & "?" -> What is the 1st letter of the word \"isasaisip\"? | E3: ="Ano ang ika-" & K3& " na titik ng salitang " & "\" & """" &I3 & "\" & """" & "?" -> Ano ang ika-1 na titik ng salitang \"isasaisip\"? | F3: i | G3: composition_character_recognition_00001 | I3: isasaisip | J3: 1st | K3: 1
A4: composition | B4: character_recognition | C4: regular | D4: ="What is the " & J4 & " letter of the word " & "\" & """" &I4 & "\" & """" & "?" -> What is the 2nd letter of the word \"nakikipag-iyutan\"? | E4: ="Ano ang ika-" & K4& " na titik ng salitang " & "\" & """" &I4 & "\" & """" & "?" -> Ano ang ika-2 na titik ng salitang \"nakikipag-iyutan\"? | F4: a | G4: composition_character_recognition_00002 | I4: nakikipag-iyutan | J4: 2nd | K4: 2
A5: composition | B5: character_recognition | C5: regular | D5: ="What is the " & J5 & " letter of the word " & "\" & """" &I5 & "\" & """" & "?" -> What is the 7th letter of the word \"kauulit\"? | E5: ="Ano ang ika-" & K5& " na titik ng salitang " & "\" & """" &I5 & "\" & """" & "?" -> Ano ang ika-8 na titik ng salitang \"kauulit\"? | F5: t | G5: composition_character_recognition_00003 | I5: kauulit | J5: 7th | K5: 8
A6: composition | B6: character_recognition | C6: regular | D6: ="What is the " & J6 & " letter of the word " & "\" & """" &I6 & "\" & """" & "?" -> What is the 1st letter of the word \"umapaw\"? | E6: ="Ano ang ika-" & K6& " na titik ng salitang " & "\" & """" &I6 & "\" & """" & "?" -> Ano ang ika-1 na titik ng salitang \"umapaw\"? | F6: u | G6: composition_character_recognition_00004 | I6: umapaw | J6: 1st | K6: 1
A7: composition | B7: character_recognition | C7: regular | D7: ="What is the " & J7 & " letter of the word " & "\" & """" &I7 & "\" & """" & "?" -> What is the 9th letter of the word \"inulyawan\"? | E7: ="Ano ang ika-" & K7& " na titik ng salitang " & "\" & """" &I7 & "\" & """" & "?" -> Ano ang ika-9 na titik ng salitang \"inulyawan\"? | F7: n | G7: composition_character_recognition_00005 | I7: inulyawan | J7: 9th | K7: 9
A8: composition | B8: character_recognition | C8: regular | D8: ="What is the " & J8 & " letter of the word " & "\" & """" &I8 & "\" & """" & "?" -> What is the 3rd letter of the word \"napakaulyanin\"? | E8: ="Ano ang ika-" & K8& " na titik ng salitang " & "\" & """" &I8 & "\" & """" & "?" -> Ano ang ika-3 na titik ng salitang \"napakaulyanin\"? | F8: p | G8: composition_character_recognition_00006 | I8: napakaulyanin | J8: 3rd | K8: 3
A9: composition | B9: character_recognition | C9: regular | D9: ="What is the " & J9 & " letter of the word " & "\" & """" &I9 & "\" & """" & "?" -> What is the 3rd letter of the word \"pag-ibayuhin\"? | E9: ="Ano ang ika-" & K9& " na titik ng salitang " & "\" & """" &I9 & "\" & """" & "?" -> Ano ang ika-3 na titik ng salitang \"pag-ibayuhin\"? | F9: g | G9: composition_character_recognition_00007 | I9: pag-ibayuhin | J9: 3rd | K9: 3
A10: composition | B10: character_recognition | C10: regular | D10: ="What is the " & J10 & " letter of the word " & "\" & """" &I10 & "\" & """" & "?" -> What is the 6th letter of the word \"alayan\"? | E10: ="Ano ang ika-" & K10& " na titik ng salitang " & "\" & """" &I10 & "\" & """" & "?" -> Ano ang ika-6 na titik ng salitang \"alayan\"? | F10: n | G10: composition_character_recognition_00008 | I10: alayan | J10: 6th | K10: 6
A11: composition | B11: character_recognition | C11: regular | D11: ="What is the " & J11 & " letter of the word " & "\" & """" &I11 & "\" & """" & "?" -> What is the 10th letter of the word \"nakakausap\"? | E11: ="Ano ang ika-" & K11& " na titik ng salitang " & "\" & """" &I11 & "\" & """" & "?" -> Ano ang ika-10 na titik ng salitang \"nakakausap\"? | F11: p | G11: composition_character_recognition_00009 | I11: nakakausap | J11: 10th | K11: 10
A12: composition | B12: character_recognition | C12: regular | D12: ="What is the " & J12 & " letter of the word " & "\" & """" &I12 & "\" & """" & "?" -> What is the 7th letter of the word \"nakapagpatutsada\"? | E12: ="Ano ang ika-" & K12& " na titik ng salitang " & "\" & """" &I12 & "\" & """" & "?" -> Ano ang ika-7 na titik ng salitang \"nakapagpatutsada\"? | F12: g | G12: composition_character_recognition_00010 | I12: nakapagpatutsada | J12: 7th | K12: 7
A13: composition | B13: character_recognition | C13: regular | D13: ="What is the " & J13 & " letter of the word " & "\" & """" &I13 & "\" & """" & "?" -> What is the 4th letter of the word \"maalalahanin\"? | E13: ="Ano ang ika-" & K13& " na titik ng salitang " & "\" & """" &I13 & "\" & """" & "?" -> Ano ang ika-4 na titik ng salitang \"maalalahanin\"? | F13: l | G13: composition_character_recognition_00011 | I13: maalalahanin | J13: 4th | K13: 4
A14: composition | B14: character_recognition | C14: regular | D14: ="What is the " & J14 & " letter of the word " & "\" & """" &I14 & "\" & """" & "?" -> What is the 5th letter of the word \"baligtad\"? | E14: ="Ano ang ika-" & K14& " na titik ng salitang " & "\" & """" &I14 & "\" & """" & "?" -> Ano ang ika-5 na titik ng salitang \"baligtad\"? | F14: g | G14: composition_character_recognition_00012 | I14: baligtad | J14: 5th | K14: 5
A15: composition | B15: character_recognition | C15: regular | D15: ="What is the " & J15 & " letter of the word " & "\" & """" &I15 & "\" & """" & "?" -> What is the 2nd letter of the word \"di-sadya\"? | E15: ="Ano ang ika-" & K15& " na titik ng salitang " & "\" & """" &I15 & "\" & """" & "?" -> Ano ang ika-2 na titik ng salitang \"di-sadya\"? | F15: i | G15: composition_character_recognition_00013 | I15: di-sadya | J15: 2nd | K15: 2
A16: composition | B16: character_recognition | C16: regular | D16: ="What is the " & J16 & " letter of the word " & "\" & """" &character_counting!H40 & "\" & """" & "?" -> What is the 1st letter of the word \"tagapanatili\"? | E16: ="Ano ang ika-" & K16& " na titik ng salitang " & "\" & """" &character_counting!H40 & "\" & """" & "?" -> Ano ang ika-1 na titik ng salitang \"tagapanatili\"? | F16: t | G16: composition_character_recognition_00014 | J16: 1st | K16: 1
A17: composition | B17: character_recognition | C17: regular | D17: ="What is the " & J17 & " letter of the word " & "\" & """" &character_counting!H41 & "\" & """" & "?" -> What is the 7th letter of the word \"magsisipagsali\"? | E17: ="Ano ang ika-" & K17& " na titik ng salitang " & "\" & """" &character_counting!H41 & "\" & """" & "?" -> Ano ang ika-7 na titik ng salitang \"magsisipagsali\"? | F17: i | G17: composition_character_recognition_00015 | J17: 7th | K17: 7
A18: composition | B18: character_recognition | C18: regular | D18: ="What is the " & J18 & " letter of the word " & "\" & """" &character_counting!H42 & "\" & """" & "?" -> What is the 3rd letter of the word \"napaglipasan\"? | E18: ="Ano ang ika-" & K18& " na titik ng salitang " & "\" & """" &character_counting!H42 & "\" & """" & "?" -> Ano ang ika-3 na titik ng salitang \"napaglipasan\"? | F18: p | G18: composition_character_recognition_00016 | J18: 3rd | K18: 3
A19: composition | B19: character_recognition | C19: regular | D19: ="What is the " & J19 & " letter of the word " & "\" & """" &character_counting!H43 & "\" & """" & "?" -> What is the 7th letter of the word \"pag-abiso\"? | E19: ="Ano ang ika-" & K19& " na titik ng salitang " & "\" & """" &character_counting!H43 & "\" & """" & "?" -> Ano ang ika-7 na titik ng salitang \"pag-abiso\"? | F19: s | G19: composition_character_recognition_00017 | J19: 7th | K19: 7
A20: composition | B20: character_recognition | C20: regular | D20: ="What is the " & J20 & " letter of the word " & "\" & """" &character_counting!H44 & "\" & """" & "?" -> What is the 4th letter of the word \"mapagtampo\"? | E20: ="Ano ang ika-" & K20& " na titik ng salitang " & "\" & """" &character_counting!H44 & "\" & """" & "?" -> Ano ang ika-4 na titik ng salitang \"mapagtampo\"? | F20: a | G20: composition_character_recognition_00018 | J20: 4th | K20: 4
A21: composition | B21: character_recognition | C21: regular | D21: ="What is the " & J21 & " letter of the word " & "\" & """" &character_counting!H45 & "\" & """" & "?" -> What is the 1st letter of the word \"simbigo\"? | E21: ="Ano ang ika-" & K21& " na titik ng salitang " & "\" & """" &character_counting!H45 & "\" & """" & "?" -> Ano ang ika-1 na titik ng salitang \"simbigo\"? | F21: s | G21: composition_character_recognition_00019 | J21: 1st | K21: 1
A22: composition | B22: character_recognition | C22: regular | D22: ="What is the " & J22 & " letter of the word " & "\" & """" &character_counting!H46 & "\" & """" & "?" -> What is the 7th letter of the word \"nagsitayo\"? | E22: ="Ano ang ika-" & K22& " na titik ng salitang " & "\" & """" &character_counting!H46 & "\" & """" & "?" -> Ano ang ika-7 na titik ng salitang \"nagsitayo\"? | F22: a | G22: composition_character_recognition_00020 | J22: 7th | K22: 7
A23: composition | B23: character_recognition | C23: regular | D23: ="What is the " & J23 & " letter of the word " & "\" & """" &character_counting!H47 & "\" & """" & "?" -> What is the 6th letter of the word \"bulate\"? | E23: ="Ano ang ika-" & K23& " na titik ng salitang " & "\" & """" &character_counting!H47 & "\" & """" & "?" -> Ano ang ika-6 na titik ng salitang \"bulate\"? | F23: e | G23: composition_character_recognition_00021 | J23: 6th | K23: 6
A24: composition | B24: character_recognition | C24: regular | D24: ="What is the " & J24 & " letter of the word " & "\" & """" &character_counting!H48 & "\" & """" & "?" -> What is the 6th letter of the word \"pinakadetalyado\"? | E24: ="Ano ang ika-" & K24& " na titik ng salitang " & "\" & """" &character_counting!H48 & "\" & """" & "?" -> Ano ang ika-6 na titik ng salitang \"pinakadetalyado\"? | F24: a | G24: composition_character_recognition_00022 | J24: 6th | K24: 6
A25: composition | B25: character_recognition | C25: regular | D25: ="What is the " & J25 & " letter of the word " & "\" & """" &character_counting!H49 & "\" & """" & "?" -> What is the 8th letter of the word \"pambubusabos\"? | E25: ="Ano ang ika-" & K25& " na titik ng salitang " & "\" & """" &character_counting!H49 & "\" & """" & "?" -> Ano ang ika-8 na titik ng salitang \"pambubusabos\"? | F25: s | G25: composition_character_recognition_00023 | J25: 8th | K25: 8
A26: composition | B26: character_recognition | C26: regular | D26: ="What is the " & J26 & " letter of the word " & "\" & """" &character_counting!H50 & "\" & """" & "?" -> What is the 10th letter of the word \"magpapasahod\"? | E26: ="Ano ang ika-" & K26& " na titik ng salitang " & "\" & """" &character_counting!H50 & "\" & """" & "?" -> Ano ang ika-10 na titik ng salitang \"magpapasahod\"? | F26: h | G26: composition_character_recognition_00024 | J26: 10th | K26: 10
A27: composition | B27: character_recognition | C27: regular | D27: ="What is the " & J27 & " letter of the word " & "\" & """" &character_counting!H51 & "\" & """" & "?" -> What is the 5th letter of the word \"paruparo\"? | E27: ="Ano ang ika-" & K27& " na titik ng salitang " & "\" & """" &character_counting!H51 & "\" & """" & "?" -> Ano ang ika-5 na titik ng salitang \"paruparo\"? | F27: p | G27: composition_character_recognition_00025 | J27: 5th | K27: 5
A28: composition | B28: character_recognition | C28: regular | D28: ="What is the " & J28 & " letter of the word " & "\" & """" &I28 & "\" & """" & "?" -> What is the 4th letter of the word \"mambubukid\"? | E28: ="Ano ang ika-" & K28& " na titik ng salitang " & "\" & """" &I28 & "\" & """" & "?" -> Ano ang ika-4 na titik ng salitang \"mambubukid\"? | F28: b | G28: composition_character_recognition_00026 | I28: mambubukid | J28: 4th | K28: 4
A29: composition | B29: character_recognition | C29: regular | D29: ="What is the " & J29 & " letter of the word " & "\" & """" &I29 & "\" & """" & "?" -> What is the 4th letter of the word \"nakaalam\"? | E29: ="Ano ang ika-" & K29& " na titik ng salitang " & "\" & """" &I29 & "\" & """" & "?" -> Ano ang ika-4 na titik ng salitang \"nakaalam\"? | F29: a | G29: composition_character_recognition_00027 | I29: nakaalam | J29: 4th | K29: 4
A30: composition | B30: character_recognition | C30: regular | D30: ="What is the " & J30 & " letter of the word " & "\" & """" &I30 & "\" & """" & "?" -> What is the 7th letter of the word \"kasintotoo\"? | E30: ="Ano ang ika-" & K30& " na titik ng salitang " & "\" & """" &I30 & "\" & """" & "?" -> Ano ang ika-7 na titik ng salitang \"kasintotoo\"? | F30: o | G30: composition_character_recognition_00028 | I30: kasintotoo | J30: 7th | K30: 7
A31: composition | B31: character_recognition | C31: regular | D31: ="What is the " & J31 & " letter of the word " & "\" & """" &I31 & "\" & """" & "?" -> What is the 4th letter of the word \"pagawaan\"? | E31: ="Ano ang ika-" & K31& " na titik ng salitang " & "\" & """" &I31 & "\" & """" & "?" -> Ano ang ika-4 na titik ng salitang \"pagawaan\"? | F31: a | G31: composition_character_recognition_00029 | I31: pagawaan | J31: 4th | K31: 4
A32: composition | B32: character_recognition | C32: regular | D32: ="What is the " & J32 & " letter of the word " & "\" & """" &I32 & "\" & """" & "?" -> What is the 7th letter of the word \"nagsakayan\"? | E32: ="Ano ang ika-" & K32& " na titik ng salitang " & "\" & """" &I32 & "\" & """" & "?" -> Ano ang ika-7 na titik ng salitang \"nagsakayan\"? | F32: a | G32: composition_character_recognition_00030 | I32: nagsakayan | J32: 7th | K32: 7
A33: composition | B33: character_recognition | C33: regular | D33: ="What is the " & J33 & " letter of the word " & "\" & """" &I33 & "\" & """" & "?" -> What is the 11th letter of the word \"mapasunod-sunod\"? | E33: ="Ano ang ika-" & K33& " na titik ng salitang " & "\" & """" &I33 & "\" & """" & "?" -> Ano ang ika-11 na titik ng salitang \"mapasunod-sunod\"? | F33: u | G33: composition_character_recognition_00031 | I33: mapasunod-sunod | J33: 11th | K33: 11
A34: composition | B34: character_recognition | C34: regular | D34: ="What is the " & J34 & " letter of the word " & "\" & """" &I34 & "\" & """" & "?" -> What is the 8th letter of the word \"magmasid-masid\"? | E34: ="Ano ang ika-" & K34& " na titik ng salitang " & "\" & """" &I34 & "\" & """" & "?" -> Ano ang ika-8 na titik ng salitang \"magmasid-masid\"? | F34: d | G34: composition_character_recognition_00032 | I34: magmasid-masid | J34: 8th | K34: 8
A35: composition | B35: character_recognition | C35: regular | D35: ="What is the " & J35 & " letter of the word " & "\" & """" &I35 & "\" & """" & "?" -> What is the 13th letter of the word \"makikipagdaldalan\"? | E35: ="Ano ang ika-" & K35& " na titik ng salitang " & "\" & """" &I35 & "\" & """" & "?" -> Ano ang ika-13 na titik ng salitang \"makikipagdaldalan\"? | F35: d | G35: composition_character_recognition_00033 | I35: makikipagdaldalan | J35: 13th | K35: 13
A36: composition | B36: character_recognition | C36: regular | D36: ="What is the " & J36 & " letter of the word " & "\" & """" &I36 & "\" & """" & "?" -> What is the 5th letter of the word \"ratsadera\"? | E36: ="Ano ang ika-" & K36& " na titik ng salitang " & "\" & """" &I36 & "\" & """" & "?" -> Ano ang ika-5 na titik ng salitang \"ratsadera\"? | F36: a | G36: composition_character_recognition_00034 | I36: ratsadera | J36: 5th | K36: 5
A37: composition | B37: character_recognition | C37: regular | D37: ="What is the " & J37 & " letter of the word " & "\" & """" &I37 & "\" & """" & "?" -> What is the 12th letter of the word \"bahay-bahayan\"? | E37: ="Ano ang ika-" & K37& " na titik ng salitang " & "\" & """" &I37 & "\" & """" & "?" -> Ano ang ika-12 na titik ng salitang \"bahay-bahayan\"? | F37: n | G37: composition_character_recognition_00035 | I37: bahay-bahayan | J37: 12th | K37: 12
A38: composition | B38: character_recognition | C38: regular | D38: ="What is the " & J38 & " letter of the word " & "\" & """" &I38 & "\" & """" & "?" -> What is the 1st letter of the word \"nagpapayat\"? | E38: ="Ano ang ika-" & K38& " na titik ng salitang " & "\" & """" &I38 & "\" & """" & "?" -> Ano ang ika-1 na titik ng salitang \"nagpapayat\"? | F38: n | G38: composition_character_recognition_00036 | I38: nagpapayat | J38: 1st | K38: 1
A39: composition | B39: character_recognition | C39: regular | D39: ="What is the " & J39 & " letter of the word " & "\" & """" &I39 & "\" & """" & "?" -> What is the 3rd letter of the word \"tagapag-ihaw\"? | E39: ="Ano ang ika-" & K39& " na titik ng salitang " & "\" & """" &I39 & "\" & """" & "?" -> Ano ang ika-3 na titik ng salitang \"tagapag-ihaw\"? | F39: g | G39: composition_character_recognition_00037 | I39: tagapag-ihaw | J39: 3rd | K39: 3
... A51: composition | B51: character_recognition | C51: regular | D51: ="What is the " & J51 & " letter of the word " & "\" & """" &I51 & "\" & """" & "?" -> What is the 6th letter of the word \"hardin\"? | E51: ="Ano ang ika-" & K51& " na titik ng salitang " & "\" & """" &I51 & "\" & """" & "?" -> Ano ang ika-6 na titik ng salitang \"hardin\"? | F51: n | G51: composition_character_recognition_00049 | I51: hardin | J51: 6th | K51: 6
...

Sheet inflected_affix_extraction
A1: category | B1: subcategory | C1: subcategory2 | D1: subcategory3 | E1: text_en | F1: text_tl | G1: label | H1: id | I1: word | J1: root_word | K1: affix | L1: affix_alternate | M1: affix_type | N1: subtype
A2: morphological_extraction | B2: inflected_affix_extraction | C2: prefix | D2: partial_assimilation | E2: What is the affix used to inflect the word \"mambola\"? | F2: Ano ang panlapi na ginamit sa salitang \"mambola\"? | G2: mang- | H2: morphological_extraction_inflected_affix_extraction_00000 | I2: mambola | J2: bola | K2: mang- | M2: prefix | N2: partial assimilation (prefix)
A3: morphological_extraction | B3: inflected_affix_extraction | C3: =M3 -> prefix | D3: partial_assimilation | E3: ="What is the affix used to inflect the word " & "\" & """" & I3 & "\" & """" & "?" -> What is the affix used to inflect the word \"mandaya\"? | F3: ="Ano ang panlapi na ginamit sa salitang " & "\" & """" & I3 & "\" & """" & "?" -> Ano ang panlapi na ginamit sa salitang \"mandaya\"? | G3: =K3 -> mang- | H3: morphological_extraction_inflected_affix_extraction_00001 | I3: mandaya | J3: daya | K3: mang- | M3: prefix | N3: partial assimilation (prefix)
A4: morphological_extraction | B4: inflected_affix_extraction | C4: =M4 -> prefix | D4: partial_assimilation | E4: ="What is the affix used to inflect the word " & "\" & """" & I4 & "\" & """" & "?" -> What is the affix used to inflect the word \"mapanlamang\"? | F4: ="Ano ang panlapi na ginamit sa salitang " & "\" & """" & I4 & "\" & """" & "?" -> Ano ang panlapi na ginamit sa salitang \"mapanlamang\"? | G4: =K4 -> mapang- | H4: morphological_extraction_inflected_affix_extraction_00002 | I4: mapanlamang | J4: lamang | K4: mapang- | M4: prefix | N4: partial assimilation (prefix)
A5: morphological_extraction | B5: inflected_affix_extraction | C5: =M5 -> prefix | D5: partial_assimilation | E5: ="What is the affix used to inflect the word " & "\" & """" & I5 & "\" & """" & "?" -> What is the affix used to inflect the word \"pambansa\"? | F5: ="Ano ang panlapi na ginamit sa salitang " & "\" & """" & I5 & "\" & """" & "?" -> Ano ang panlapi na ginamit sa salitang \"pambansa\"? | G5: =K5 -> pang- | H5: morphological_extraction_inflected_affix_extraction_00003 | I5: pambansa | J5: bansa | K5: pang- | M5: prefix | N5: partial assimilation (prefix)
A6: morphological_extraction | B6: inflected_affix_extraction | C6: =M6 -> prefix | D6: partial_assimilation | E6: ="What is the affix used to inflect the word " & "\" & """" & I6 & "\" & """" & "?" -> What is the affix used to inflect the word \"pampito\"? | F6: ="Ano ang panlapi na ginamit sa salitang " & "\" & """" & I6 & "\" & """" & "?" -> Ano ang panlapi na ginamit sa salitang \"pampito\"? | G6: =K6 -> pang- | H6: morphological_extraction_inflected_affix_extraction_00004 | I6: pampito | J6: pito | K6: pang- | M6: prefix | N6: partial assimilation (prefix)
A7: morphological_extraction | B7: inflected_affix_extraction | C7: =M7 -> prefix | D7: partial_assimilation | E7: ="What is the affix used to inflect the word " & "\" & """" & I7 & "\" & """" & "?" -> What is the affix used to inflect the word \"nanlaban\"? | F7: ="Ano ang panlapi na ginamit sa salitang " & "\" & """" & I7 & "\" & """" & "?" -> Ano ang panlapi na ginamit sa salitang \"nanlaban\"? | G7: =K7 -> nang- | H7: morphological_extraction_inflected_affix_extraction_00005 | I7: nanlaban | J7: laban | K7: nang- | M7: prefix | N7: partial assimilation (prefix)
A8: morphological_extraction | B8: inflected_affix_extraction | C8: =M8 -> prefix | D8: partial_assimilation | E8: ="What is the affix used to inflect the word " & "\" & """" & I8 & "\" & """" & "?" -> What is the affix used to inflect the word \"ipampinta\"? | F8: ="Ano ang panlapi na ginamit sa salitang " & "\" & """" & I8 & "\" & """" & "?" -> Ano ang panlapi na ginamit sa salitang \"ipampinta\"? | G8: =K8 -> nang- | H8: morphological_extraction_inflected_affix_extraction_00006 | I8: ipampinta | J8: pinta | K8: nang- | M8: prefix | N8: partial assimilation (prefix)
A9: morphological_extraction | B9: inflected_affix_extraction | C9: =M9 -> prefix | D9: partial_assimilation | E9: ="What is the affix used to inflect the word " & "\" & """" & I9 & "\" & """" & "?" -> What is the affix used to inflect the word \"ipantapal\"? | F9: ="Ano ang panlapi na ginamit sa salitang " & "\" & """" & I9 & "\" & """" & "?" -> Ano ang panlapi na ginamit sa salitang \"ipantapal\"? | G9: =K9 -> ipang- | H9: morphological_extraction_inflected_affix_extraction_00007 | I9: ipantapal | J9: tapal | K9: ipang- | M9: prefix | N9: partial assimilation (prefix)
A10: morphological_extraction | B10: inflected_affix_extraction | C10: =M10 -> prefix | D10: partial_assimilation | E10: ="What is the affix used to inflect the word " & "\" & """" & I10 & "\" & """" & "?" -> What is the affix used to inflect the word \"simbait\"? | F10: ="Ano ang panlapi na ginamit sa salitang " & "\" & """" & I10 & "\" & """" & "?" -> Ano ang panlapi na ginamit sa salitang \"simbait\"? | G10: =K10 -> sing- | H10: morphological_extraction_inflected_affix_extraction_00008 | I10: simbait | J10: bait | K10: sing- | M10: prefix | N10: partial assimilation (prefix)
A11: morphological_extraction | B11: inflected_affix_extraction | C11: =M11 -> prefix | D11: partial_assimilation | E11: ="What is the affix used to inflect the word " & "\" & """" & I11 & "\" & """" & "?" -> What is the affix used to inflect the word \"sintibay\"? | F11: ="Ano ang panlapi na ginamit sa salitang " & "\" & """" & I11 & "\" & """" & "?" -> Ano ang panlapi na ginamit sa salitang \"sintibay\"? | G11: =K11 -> sing- | H11: morphological_extraction_inflected_affix_extraction_00009 | I11: sintibay | J11: tibay | K11: sing- | M11: prefix | N11: partial assimilation (prefix)
A12: morphological_extraction | B12: inflected_affix_extraction | C12: =M12 -> prefix | D12: full_assimilation | E12: ="What is the affix used to inflect the word " & "\" & """" & I12 & "\" & """" & "?" -> What is the affix used to inflect the word \"panguha\"? | F12: ="Ano ang panlapi na ginamit sa salitang " & "\" & """" & I12 & "\" & """" & "?" -> Ano ang panlapi na ginamit sa salitang \"panguha\"? | G12: =K12 -> pang- | H12: morphological_extraction_inflected_affix_extraction_00010 | I12: panguha | J12: kuha | K12: pang- | M12: prefix | N12: full assimilation (prefix)
A13: morphological_extraction | B13: inflected_affix_extraction | C13: =M13 -> prefix | D13: full_assimilation | E13: ="What is the affix used to inflect the word " & "\" & """" & I13 & "\" & """" & "?" -> What is the affix used to inflect the word \"panabas\"? | F13: ="Ano ang panlapi na ginamit sa salitang " & "\" & """" & I13 & "\" & """" & "?" -> Ano ang panlapi na ginamit sa salitang \"panabas\"? | G13: =K13 -> pang- | H13: morphological_extraction_inflected_affix_extraction_00011 | I13: panabas | J13: tabas | K13: pang- | M13: prefix | N13: full assimilation (prefix)
A14: morphological_extraction | B14: inflected_affix_extraction | C14: =M14 -> prefix | D14: full_assimilation | E14: ="What is the affix used to inflect the word " & "\" & """" & I14 & "\" & """" & "?" -> What is the affix used to inflect the word \"pamatay\"? | F14: ="Ano ang panlapi na ginamit sa salitang " & "\" & """" & I14 & "\" & """" & "?" -> Ano ang panlapi na ginamit sa salitang \"pamatay\"? | G14: =K14 -> pang- | H14: morphological_extraction_inflected_affix_extraction_00012 | I14: pamatay | J14: patay | K14: pang- | M14: prefix | N14: full assimilation (prefix)
... A64: morphological_extraction | B64: inflected_affix_extraction | C64: =M64 -> suffix | D64: phoneme_change | E64: ="What is the affix used to inflect the word " & "\" & """" & I64 & "\" & """" & "?" -> What is the affix used to inflect the word \"sabugan\"? | F64: ="Ano ang panlapi na ginamit sa salitang " & "\" & """" & I64 & "\" & """" & "?" -> Ano ang panlapi na ginamit sa salitang \"sabugan\"? | G64: =K64 -> -an | H64: morphological_extraction_inflected_affix_extraction_00062 | I64: sabugan | J64: sabog | K64: -an | M64: suffix | N64: phoneme change (suffix)
A65: morphological_extraction | B65: inflected_affix_extraction | C65: =M65 -> suffix | D65: phoneme_change | E65: ="What is the affix used to inflect the word " & "\" & """" & I65 & "\" & """" & "?" -> What is the affix used to inflect the word \"batuhin\"? | F65: ="Ano ang panlapi na ginamit sa salitang " & "\" & """" & I65 & "\" & """" & "?" -> Ano ang panlapi na ginamit sa salitang \"batuhin\"? | G65: =K65 -> -hin | H65: morphological_extraction_inflected_affix_extraction_00063 | I65: batuhin | J65: bato | K65: -hin | L65: -in | M65: suffix | N65: phoneme change (suffix)
A66: morphological_extraction | B66: inflected_affix_extraction | C66: =M66 -> suffix | D66: phoneme_change | E66: ="What is the affix used to inflect the word " & "\" & """" & I66 & "\" & """" & "?" -> What is the affix used to inflect the word \"sikuhin\"? | F66: ="Ano ang panlapi na ginamit sa salitang " & "\" & """" & I66 & "\" & """" & "?" -> Ano ang panlapi na ginamit sa salitang \"sikuhin\"? | G66: =K66 -> -hin | H66: morphological_extraction_inflected_affix_extraction_00064 | I66: sikuhin | J66: siko | K66: -hin | L66: -in | M66: suffix | N66: phoneme change (suffix)
A67: morphological_extraction | B67: inflected_affix_extraction | C67: =M67 -> suffix | D67: phoneme_change | E67: ="What is the affix used to inflect the word " & "\" & """" & I67 & "\" & """" & "?" -> What is the affix used to inflect the word \"puruhan\"? | F67: ="Ano ang panlapi na ginamit sa salitang " & "\" & """" & I67 & "\" & """" & "?" -> Ano ang panlapi na ginamit sa salitang \"puruhan\"? | G67: =K67 -> -han | H67: morphological_extraction_inflected_affix_extraction_00065 | I67: puruhan | J67: puro | K67: -han | L67: -an | M67: suffix | N67: phoneme change (suffix)
A68: morphological_extraction | B68: inflected_affix_extraction | C68: =M68 -> suffix | D68: phoneme_change | E68: ="What is the affix used to inflect the word " & "\" & """" & I68 & "\" & """" & "?" -> What is the affix used to inflect the word \"baguhin\"? | F68: ="Ano ang panlapi na ginamit sa salitang " & "\" & """" & I68 & "\" & """" & "?" -> Ano ang panlapi na ginamit sa salitang \"baguhin\"? | G68: =K68 -> -hin | H68: morphological_extraction_inflected_affix_extraction_00066 | I68: baguhin | J68: bago | K68: -hin | L68: -in | M68: suffix | N68: phoneme change (suffix)
A69: morphological_extraction | B69: inflected_affix_extraction | C69: =M69 -> suffix | D69: phoneme_change | E69: ="What is the affix used to inflect the word " & "\" & """" & I69 & "\" & """" & "?" -> What is the affix used to inflect the word \"uluhan\"? | F69: ="Ano ang panlapi na ginamit sa salitang " & "\" & """" & I69 & "\" & """" & "?" -> Ano ang panlapi na ginamit sa salitang \"uluhan\"? | G69: =K69 -> -han | H69: morphological_extraction_inflected_affix_extraction_00067 | I69: uluhan | J69: ulo | K69: -han | L69: -an | M69: suffix | N69: phoneme change (suffix)
A70: morphological_extraction | B70: inflected_affix_extraction | C70: =M70 -> suffix | D70: phoneme_change | E70: ="What is the affix used to inflect the word " & "\" & """" & I70 & "\" & """" & "?" -> What is the affix used to inflect the word \"guluhin\"? | F70: ="Ano ang panlapi na ginamit sa salitang " & "\" & """" & I70 & "\" & """" & "?" -> Ano ang panlapi na ginamit sa salitang \"guluhin\"? | G70: =K70 -> -hin | H70: morphological_extraction_inflected_affix_extraction_00068 | I70: guluhin | J70: gulo | K70: -hin | L70: -in | M70: suffix | N70: phoneme change (suffix)
A71: morphological_extraction | B71: inflected_affix_extraction | C71: =M71 -> suffix | D71: phoneme_change | E71: ="What is the affix used to inflect the word " & "\" & """" & I71 & "\" & """" & "?" -> What is the affix used to inflect the word \"tawanan\"? | F71: ="Ano ang panlapi na ginamit sa salitang " & "\" & """" & I71 & "\" & """" & "?" -> Ano ang panlapi na ginamit sa salitang \"tawanan\"? | G71: =K71 -> -han | H71: morphological_extraction_inflected_affix_extraction_00069 | I71: tawanan | J71: tawa | K71: -han | L71: -an | M71: suffix | N71: phoneme change (suffix)
A72: morphological_extraction | B72: inflected_affix_extraction | C72: =M72 -> suffix | D72: phoneme_deletion | E72: ="What is the affix used to inflect the word " & "\" & """" & I72 & "\" & """" & "?" -> What is the affix used to inflect the word \"takpan\"? | F72: ="Ano ang panlapi na ginamit sa salitang " & "\" & """" & I72 & "\" & """" & "?" -> Ano ang panlapi na ginamit sa salitang \"takpan\"? | G72: =K72 -> -an | H72: morphological_extraction_inflected_affix_extraction_00070 | I72: takpan | J72: takip | K72: -an | M72: suffix | N72: phoneme deletion (suffix)
A73: morphological_extraction | B73: inflected_affix_extraction | C73: =M73 -> suffix | D73: phoneme_deletion | E73: ="What is the affix used to inflect the word " & "\" & """" & I73 & "\" & """" & "?" -> What is the affix used to inflect the word \"saktan\"? | F73: ="Ano ang panlapi na ginamit sa salitang " & "\" & """" & I73 & "\" & """" & "?" -> Ano ang panlapi na ginamit sa salitang \"saktan\"? | G73: =K73 -> -an | H73: morphological_extraction_inflected_affix_extraction_00071 | I73: saktan | J73: sakit | K73: -an | M73: suffix | N73: phoneme deletion (suffix)
A74: morphological_extraction | B74: inflected_affix_extraction | C74: =M74 -> suffix | D74: phoneme_deletion | E74: ="What is the affix used to inflect the word " & "\" & """" & I74 & "\" & """" & "?" -> What is the affix used to inflect the word \"buksan\"? | F74: ="Ano ang panlapi na ginamit sa salitang " & "\" & """" & I74 & "\" & """" & "?" -> Ano ang panlapi na ginamit sa salitang \"buksan\"? | G74: =K74 -> -an | H74: morphological_extraction_inflected_affix_extraction_00072 | I74: buksan | J74: bukas | K74: -an | M74: suffix | N74: phoneme deletion (suffix)
A75: morphological_extraction | B75: inflected_affix_extraction | C75: =M75 -> suffix | D75: phoneme_deletion | E75: ="What is the affix used to inflect the word " & "\" & """" & I75 & "\" & """" & "?" -> What is the affix used to inflect the word \"sundin\"? | F75: ="Ano ang panlapi na ginamit sa salitang " & "\" & """" & I75 & "\" & """" & "?" -> Ano ang panlapi na ginamit sa salitang \"sundin\"? | G75: =K75 -> -in | H75: morphological_extraction_inflected_affix_extraction_00073 | I75: sundin | J75: sunod | K75: -in | M75: suffix | N75: phoneme deletion (suffix)
A76: morphological_extraction | B76: inflected_affix_extraction | C76: =M76 -> suffix | D76: phoneme_deletion | E76: ="What is the affix used to inflect the word " & "\" & """" & I76 & "\" & """" & "?" -> What is the affix used to inflect the word \"tupdin\"? | F76: ="Ano ang panlapi na ginamit sa salitang " & "\" & """" & I76 & "\" & """" & "?" -> Ano ang panlapi na ginamit sa salitang \"tupdin\"? | G76: =K76 -> -in | H76: morphological_extraction_inflected_affix_extraction_00074 | I76: tupdin | J76: tupad | K76: -in | M76: suffix | N76: phoneme deletion (suffix)
